Traceback (most recent call last):
  File "/Users/khangnghiem/.pyenv/versions/3.11.4/lib/python3.11/site-packages/nbclient/client.py", line 782, in _async_poll_for_reply
    msg = await ensure_async(self.kc.shell_channel.get_msg(timeout=new_timeout))
          ^^^^^^^^^^^^^^^^^^^^^^^^^^^^^^^^^^^^^^^^^^^^^^^^^^^^^^^^^^^^^^^^^^^^^^
  File "/Users/khangnghiem/.local/lib/python3.11/site-packages/jupyter_core/utils/__init__.py", line 189, in ensure_async
    result = await obj
             ^^^^^^^^^
  File "/Users/khangnghiem/.local/lib/python3.11/site-packages/jupyter_client/channels.py", line 315, in get_msg
    raise Empty
_queue.Empty

During handling of the above exception, another exception occurred:

Traceback (most recent call last):
  File "/Users/khangnghiem/.pyenv/versions/3.11.4/lib/python3.11/site-packages/jupyter_cache/executors/utils.py", line 58, in single_nb_execution
    executenb(
  File "/Users/khangnghiem/.pyenv/versions/3.11.4/lib/python3.11/site-packages/nbclient/client.py", line 1314, in execute
    return NotebookClient(nb=nb, resources=resources, km=km, **kwargs).execute()
           ^^^^^^^^^^^^^^^^^^^^^^^^^^^^^^^^^^^^^^^^^^^^^^^^^^^^^^^^^^^^^^^^^^^^^
  File "/Users/khangnghiem/.local/lib/python3.11/site-packages/jupyter_core/utils/__init__.py", line 173, in wrapped
    return loop.run_until_complete(inner)
           ^^^^^^^^^^^^^^^^^^^^^^^^^^^^^^
  File "/Users/khangnghiem/.pyenv/versions/3.11.4/lib/python3.11/asyncio/base_events.py", line 653, in run_until_complete
    return future.result()
           ^^^^^^^^^^^^^^^
  File "/Users/khangnghiem/.pyenv/versions/3.11.4/lib/python3.11/site-packages/nbclient/client.py", line 709, in async_execute
    await self.async_execute_cell(
  File "/Users/khangnghiem/.pyenv/versions/3.11.4/lib/python3.11/site-packages/nbclient/client.py", line 1005, in async_execute_cell
    exec_reply = await self.task_poll_for_reply
                 ^^^^^^^^^^^^^^^^^^^^^^^^^^^^^^
  File "/Users/khangnghiem/.pyenv/versions/3.11.4/lib/python3.11/site-packages/nbclient/client.py", line 806, in _async_poll_for_reply
    error_on_timeout_execute_reply = await self._async_handle_timeout(timeout, cell)
                                     ^^^^^^^^^^^^^^^^^^^^^^^^^^^^^^^^^^^^^^^^^^^^^^^
  File "/Users/khangnghiem/.pyenv/versions/3.11.4/lib/python3.11/site-packages/nbclient/client.py", line 856, in _async_handle_timeout
    raise CellTimeoutError.error_from_timeout_and_cell(
nbclient.exceptions.CellTimeoutError: A cell timed out while it was being executed, after 30 seconds.
The message was: Cell execution timed out.
Here is a preview of the cell contents:
-------------------
['from sklearn.model_selection import train_test_split', 'import polars as pl', 'import pandas as pd', 'from sklearn.tree import DecisionTreeRegressor', '']
...
['', 'body_mass_model = DecisionTreeRegressor(random_state=0)', 'body_mass_model.fit(X_train, y_train)', 'body_mass_preds = body_mass_model.predict(X_valid)', 'body_mass_preds']
-------------------

